Physician signup validation error: {'first_name': [ErrorDetail(string='This field is required.', code='required')], 'last_name': [ErrorDetail(string='This field is required.', code='required')]}
Physician signup validation error: {'first_name': [ErrorDetail(string='This field is required.', code='required')], 'last_name': [ErrorDetail(string='This field is required.', code='required')]}
Physician signup validation error: {'first_name': [ErrorDetail(string='This field is required.', code='required')], 'last_name': [ErrorDetail(string='This field is required.', code='required')]}
Internal Server Error: /login/
Traceback (most recent call last):
  File "/Users/yueyangyu01/cs/new_backend/project/venv/lib/python3.11/site-packages/django/core/handlers/exception.py", line 55, in inner
    response = get_response(request)
               ^^^^^^^^^^^^^^^^^^^^^
  File "/Users/yueyangyu01/cs/new_backend/project/venv/lib/python3.11/site-packages/django/core/handlers/base.py", line 197, in _get_response
    response = wrapped_callback(request, *callback_args, **callback_kwargs)
               ^^^^^^^^^^^^^^^^^^^^^^^^^^^^^^^^^^^^^^^^^^^^^^^^^^^^^^^^^^^^
  File "/Users/yueyangyu01/cs/new_backend/project/venv/lib/python3.11/site-packages/django/views/decorators/csrf.py", line 65, in _view_wrapper
    return view_func(request, *args, **kwargs)
           ^^^^^^^^^^^^^^^^^^^^^^^^^^^^^^^^^^^
  File "/Users/yueyangyu01/cs/new_backend/project/venv/lib/python3.11/site-packages/django/views/generic/base.py", line 104, in view
    return self.dispatch(request, *args, **kwargs)
           ^^^^^^^^^^^^^^^^^^^^^^^^^^^^^^^^^^^^^^^
  File "/Users/yueyangyu01/cs/new_backend/project/venv/lib/python3.11/site-packages/rest_framework/views.py", line 509, in dispatch
    response = self.handle_exception(exc)
               ^^^^^^^^^^^^^^^^^^^^^^^^^^
  File "/Users/yueyangyu01/cs/new_backend/project/venv/lib/python3.11/site-packages/rest_framework/views.py", line 469, in handle_exception
    self.raise_uncaught_exception(exc)
  File "/Users/yueyangyu01/cs/new_backend/project/venv/lib/python3.11/site-packages/rest_framework/views.py", line 480, in raise_uncaught_exception
    raise exc
  File "/Users/yueyangyu01/cs/new_backend/project/venv/lib/python3.11/site-packages/rest_framework/views.py", line 506, in dispatch
    response = handler(request, *args, **kwargs)
               ^^^^^^^^^^^^^^^^^^^^^^^^^^^^^^^^^
  File "/Users/yueyangyu01/cs/new_backend/project/app/views.py", line 53, in post
    user = authenticate(request, email=email, password=password)
           ^^^^^^^^^^^^^^^^^^^^^^^^^^^^^^^^^^^^^^^^^^^^^^^^^^^^^
  File "/Users/yueyangyu01/cs/new_backend/project/venv/lib/python3.11/site-packages/django/views/decorators/debug.py", line 75, in sensitive_variables_wrapper
    return func(*func_args, **func_kwargs)
           ^^^^^^^^^^^^^^^^^^^^^^^^^^^^^^^
  File "/Users/yueyangyu01/cs/new_backend/project/venv/lib/python3.11/site-packages/django/contrib/auth/__init__.py", line 70, in authenticate
    for backend, backend_path in _get_backends(return_tuples=True):
                                 ^^^^^^^^^^^^^^^^^^^^^^^^^^^^^^^^^
  File "/Users/yueyangyu01/cs/new_backend/project/venv/lib/python3.11/site-packages/django/contrib/auth/__init__.py", line 29, in _get_backends
    backend = load_backend(backend_path)
              ^^^^^^^^^^^^^^^^^^^^^^^^^^
  File "/Users/yueyangyu01/cs/new_backend/project/venv/lib/python3.11/site-packages/django/contrib/auth/__init__.py", line 23, in load_backend
    return import_string(path)()
           ^^^^^^^^^^^^^^^^^^^
  File "/Users/yueyangyu01/cs/new_backend/project/venv/lib/python3.11/site-packages/django/utils/module_loading.py", line 30, in import_string
    return cached_import(module_path, class_name)
           ^^^^^^^^^^^^^^^^^^^^^^^^^^^^^^^^^^^^^^
  File "/Users/yueyangyu01/cs/new_backend/project/venv/lib/python3.11/site-packages/django/utils/module_loading.py", line 15, in cached_import
    module = import_module(module_path)
             ^^^^^^^^^^^^^^^^^^^^^^^^^^
  File "/Users/yueyangyu01/anaconda3/lib/python3.11/importlib/__init__.py", line 126, in import_module
    return _bootstrap._gcd_import(name[level:], package, level)
           ^^^^^^^^^^^^^^^^^^^^^^^^^^^^^^^^^^^^^^^^^^^^^^^^^^^^
  File "<frozen importlib._bootstrap>", line 1204, in _gcd_import
  File "<frozen importlib._bootstrap>", line 1176, in _find_and_load
  File "<frozen importlib._bootstrap>", line 1140, in _find_and_load_unlocked
ModuleNotFoundError: No module named 'app.backends'
Internal Server Error: /login/
Traceback (most recent call last):
  File "/Users/yueyangyu01/cs/new_backend/project/venv/lib/python3.11/site-packages/django/db/backends/utils.py", line 105, in _execute
    return self.cursor.execute(sql, params)
           ^^^^^^^^^^^^^^^^^^^^^^^^^^^^^^^^
  File "/Users/yueyangyu01/cs/new_backend/project/venv/lib/python3.11/site-packages/django/db/backends/sqlite3/base.py", line 329, in execute
    return super().execute(query, params)
           ^^^^^^^^^^^^^^^^^^^^^^^^^^^^^^
sqlite3.OperationalError: no such column: app_physician.is_superuser

The above exception was the direct cause of the following exception:

Traceback (most recent call last):
  File "/Users/yueyangyu01/cs/new_backend/project/venv/lib/python3.11/site-packages/django/core/handlers/exception.py", line 55, in inner
    response = get_response(request)
               ^^^^^^^^^^^^^^^^^^^^^
  File "/Users/yueyangyu01/cs/new_backend/project/venv/lib/python3.11/site-packages/django/core/handlers/base.py", line 197, in _get_response
    response = wrapped_callback(request, *callback_args, **callback_kwargs)
               ^^^^^^^^^^^^^^^^^^^^^^^^^^^^^^^^^^^^^^^^^^^^^^^^^^^^^^^^^^^^
  File "/Users/yueyangyu01/cs/new_backend/project/venv/lib/python3.11/site-packages/django/views/decorators/csrf.py", line 65, in _view_wrapper
    return view_func(request, *args, **kwargs)
           ^^^^^^^^^^^^^^^^^^^^^^^^^^^^^^^^^^^
  File "/Users/yueyangyu01/cs/new_backend/project/venv/lib/python3.11/site-packages/django/views/generic/base.py", line 104, in view
    return self.dispatch(request, *args, **kwargs)
           ^^^^^^^^^^^^^^^^^^^^^^^^^^^^^^^^^^^^^^^
  File "/Users/yueyangyu01/cs/new_backend/project/venv/lib/python3.11/site-packages/rest_framework/views.py", line 509, in dispatch
    response = self.handle_exception(exc)
               ^^^^^^^^^^^^^^^^^^^^^^^^^^
  File "/Users/yueyangyu01/cs/new_backend/project/venv/lib/python3.11/site-packages/rest_framework/views.py", line 469, in handle_exception
    self.raise_uncaught_exception(exc)
  File "/Users/yueyangyu01/cs/new_backend/project/venv/lib/python3.11/site-packages/rest_framework/views.py", line 480, in raise_uncaught_exception
    raise exc
  File "/Users/yueyangyu01/cs/new_backend/project/venv/lib/python3.11/site-packages/rest_framework/views.py", line 506, in dispatch
    response = handler(request, *args, **kwargs)
               ^^^^^^^^^^^^^^^^^^^^^^^^^^^^^^^^^
  File "/Users/yueyangyu01/cs/new_backend/project/app/views.py", line 56, in post
    user = authenticate(request, username=email, password=password)
           ^^^^^^^^^^^^^^^^^^^^^^^^^^^^^^^^^^^^^^^^^^^^^^^^^^^^^^^^
  File "/Users/yueyangyu01/cs/new_backend/project/venv/lib/python3.11/site-packages/django/views/decorators/debug.py", line 75, in sensitive_variables_wrapper
    return func(*func_args, **func_kwargs)
           ^^^^^^^^^^^^^^^^^^^^^^^^^^^^^^^
  File "/Users/yueyangyu01/cs/new_backend/project/venv/lib/python3.11/site-packages/django/contrib/auth/__init__.py", line 79, in authenticate
    user = backend.authenticate(request, **credentials)
           ^^^^^^^^^^^^^^^^^^^^^^^^^^^^^^^^^^^^^^^^^^^^
  File "/Users/yueyangyu01/cs/new_backend/project/app/backends.py", line 8, in authenticate
    user = UserModel.objects.get(email=username)
           ^^^^^^^^^^^^^^^^^^^^^^^^^^^^^^^^^^^^^
  File "/Users/yueyangyu01/cs/new_backend/project/venv/lib/python3.11/site-packages/django/db/models/manager.py", line 87, in manager_method
    return getattr(self.get_queryset(), name)(*args, **kwargs)
           ^^^^^^^^^^^^^^^^^^^^^^^^^^^^^^^^^^^^^^^^^^^^^^^^^^^
  File "/Users/yueyangyu01/cs/new_backend/project/venv/lib/python3.11/site-packages/django/db/models/query.py", line 645, in get
    num = len(clone)
          ^^^^^^^^^^
  File "/Users/yueyangyu01/cs/new_backend/project/venv/lib/python3.11/site-packages/django/db/models/query.py", line 382, in __len__
    self._fetch_all()
  File "/Users/yueyangyu01/cs/new_backend/project/venv/lib/python3.11/site-packages/django/db/models/query.py", line 1928, in _fetch_all
    self._result_cache = list(self._iterable_class(self))
                         ^^^^^^^^^^^^^^^^^^^^^^^^^^^^^^^^
  File "/Users/yueyangyu01/cs/new_backend/project/venv/lib/python3.11/site-packages/django/db/models/query.py", line 91, in __iter__
    results = compiler.execute_sql(
              ^^^^^^^^^^^^^^^^^^^^^
  File "/Users/yueyangyu01/cs/new_backend/project/venv/lib/python3.11/site-packages/django/db/models/sql/compiler.py", line 1562, in execute_sql
    cursor.execute(sql, params)
  File "/Users/yueyangyu01/cs/new_backend/project/venv/lib/python3.11/site-packages/django/db/backends/utils.py", line 122, in execute
    return super().execute(sql, params)
           ^^^^^^^^^^^^^^^^^^^^^^^^^^^^
  File "/Users/yueyangyu01/cs/new_backend/project/venv/lib/python3.11/site-packages/django/db/backends/utils.py", line 79, in execute
    return self._execute_with_wrappers(
           ^^^^^^^^^^^^^^^^^^^^^^^^^^^^
  File "/Users/yueyangyu01/cs/new_backend/project/venv/lib/python3.11/site-packages/django/db/backends/utils.py", line 92, in _execute_with_wrappers
    return executor(sql, params, many, context)
           ^^^^^^^^^^^^^^^^^^^^^^^^^^^^^^^^^^^^
  File "/Users/yueyangyu01/cs/new_backend/project/venv/lib/python3.11/site-packages/django/db/backends/utils.py", line 100, in _execute
    with self.db.wrap_database_errors:
  File "/Users/yueyangyu01/cs/new_backend/project/venv/lib/python3.11/site-packages/django/db/utils.py", line 91, in __exit__
    raise dj_exc_value.with_traceback(traceback) from exc_value
  File "/Users/yueyangyu01/cs/new_backend/project/venv/lib/python3.11/site-packages/django/db/backends/utils.py", line 105, in _execute
    return self.cursor.execute(sql, params)
           ^^^^^^^^^^^^^^^^^^^^^^^^^^^^^^^^
  File "/Users/yueyangyu01/cs/new_backend/project/venv/lib/python3.11/site-packages/django/db/backends/sqlite3/base.py", line 329, in execute
    return super().execute(query, params)
           ^^^^^^^^^^^^^^^^^^^^^^^^^^^^^^
django.db.utils.OperationalError: no such column: app_physician.is_superuser
Patient creation error: {'first_name': [ErrorDetail(string='This field is required.', code='required')], 'last_name': [ErrorDetail(string='This field is required.', code='required')]}
Patient creation error: {'first_name': [ErrorDetail(string='This field is required.', code='required')], 'last_name': [ErrorDetail(string='This field is required.', code='required')]}
Patient creation error: {'first_name': [ErrorDetail(string='This field is required.', code='required')], 'last_name': [ErrorDetail(string='This field is required.', code='required')]}
Patient creation error: {'first_name': [ErrorDetail(string='This field is required.', code='required')], 'last_name': [ErrorDetail(string='This field is required.', code='required')]}
